Workbook

Sheet alfa
A1: Дата | B1: Назначение платежа | C1: Категория | D1: Сумма платежа | E1: key
A2: 30.05.2026 | B2: MOSCOW/IVI.RU | C2: Прочие расходы | D2: -299 | E2: проч
A3: 29.05.2026 | B3: Кристина Х. | C3: Финансовые операции | D3: -1850 | E3: Ек
A4: 29.05.2026 | B4: билайн | C4: Связь, интернет и ТВ | D4: -1100 | E4: комм.пл
A5: 28.05.2026 | B5: Сусанна Г. | C5: Финансовые операции | D5: -1400 | E5: Ек
A6: 27.05.2026 | B6: MOSCOW\IVI RU | C6: Прочие расходы | D6: -449 | E6: подписки
A7: 25.05.2026 | B7: Арина В. | C7: Финансовые операции | D7: -1000 | E7: Ар
A8: 21.05.2026 | B8: Андрей В. | C8: Финансовые операции | D8: -60000 | E8: перевод
A9: 21.05.2026 | B9: Арина В. | C9: Финансовые операции | D9: -16000 | E9: Ар
A10: 21.05.2026 | B10: ПАО "НК "Роснефть" | C10: Пополнения | D10: 76747.41 | E10: з/п
A11: 21.05.2026 | B11: УФК по Тульской области(МИ ФНС РОССИИ ПО УПРАВЛЕНИЮ ДОЛГОМ) | C11: Пополнения | D11: 7409 | E11: невыясн
A12: 19.05.2026 | B12: Гюндуз Г. | C12: Финансовые операции | D12: -1295 | E12: Ек
A13: 18.05.2026 | B13: Андрей В. | C13: Финансовые операции | D13: -10000 | E13: перевод
... A47: 01.05.2026 | B47: MOSCOW\DOSTAVKA IZ PYATEROCH | C47: Продукты | D47: -1479.2 | E47: супер.м

Sheet Лист1
A1: Дата | B1: Назначение платежа | C1: Категория | D1: Сумма платежа | E1: key
A2: =IF(alfa!A2<>"",alfa!A2,"") | B2: =IF(alfa!B2<>"",alfa!B2,"") | C2: =IF(alfa!C2<>"",alfa!C2,"") | D2: =IF(AND(alfa!D2<>"",alfa!D2<>" "),alfa!D2*1,"") | E2: =IF(alfa!E2<>"",alfa!E2,"") | F2: =IF(D2="","",IF(OR(E2="",E2="невыясн"),"!",""))
A3: =IF(alfa!A3<>"",alfa!A3,"") | B3: =IF(alfa!B3<>"",alfa!B3,"") | C3: =IF(alfa!C3<>"",alfa!C3,"") | D3: =IF(AND(alfa!D3<>"",alfa!D3<>" "),alfa!D3*1,"") | E3: =IF(alfa!E3<>"",alfa!E3,"") | F3: =IF(D3="","",IF(OR(E3="",E3="невыясн"),"!",""))
A4: =IF(alfa!A4<>"",alfa!A4,"") | B4: =IF(alfa!B4<>"",alfa!B4,"") | C4: =IF(alfa!C4<>"",alfa!C4,"") | D4: =IF(AND(alfa!D4<>"",alfa!D4<>" "),alfa!D4*1,"") | E4: =IF(alfa!E4<>"",alfa!E4,"") | F4: =IF(D4="","",IF(OR(E4="",E4="невыясн"),"!",""))
A5: =IF(alfa!A5<>"",alfa!A5,"") | B5: =IF(alfa!B5<>"",alfa!B5,"") | C5: =IF(alfa!C5<>"",alfa!C5,"") | D5: =IF(AND(alfa!D5<>"",alfa!D5<>" "),alfa!D5*1,"") | E5: =IF(alfa!E5<>"",alfa!E5,"") | F5: =IF(D5="","",IF(OR(E5="",E5="невыясн"),"!",""))
A6: =IF(alfa!A6<>"",alfa!A6,"") | B6: =IF(alfa!B6<>"",alfa!B6,"") | C6: =IF(alfa!C6<>"",alfa!C6,"") | D6: =IF(AND(alfa!D6<>"",alfa!D6<>" "),alfa!D6*1,"") | E6: =IF(alfa!E6<>"",alfa!E6,"") | F6: =IF(D6="","",IF(OR(E6="",E6="невыясн"),"!",""))
A7: =IF(alfa!A7<>"",alfa!A7,"") | B7: =IF(alfa!B7<>"",alfa!B7,"") | C7: =IF(alfa!C7<>"",alfa!C7,"") | D7: =IF(AND(alfa!D7<>"",alfa!D7<>" "),alfa!D7*1,"") | E7: =IF(alfa!E7<>"",alfa!E7,"") | F7: =IF(D7="","",IF(OR(E7="",E7="невыясн"),"!",""))
A8: =IF(alfa!A8<>"",alfa!A8,"") | B8: =IF(alfa!B8<>"",alfa!B8,"") | C8: =IF(alfa!C8<>"",alfa!C8,"") | D8: =IF(AND(alfa!D8<>"",alfa!D8<>" "),alfa!D8*1,"") | E8: =IF(alfa!E8<>"",alfa!E8,"") | F8: =IF(D8="","",IF(OR(E8="",E8="невыясн"),"!",""))
A9: =IF(alfa!A9<>"",alfa!A9,"") | B9: =IF(alfa!B9<>"",alfa!B9,"") | C9: =IF(alfa!C9<>"",alfa!C9,"") | D9: =IF(AND(alfa!D9<>"",alfa!D9<>" "),alfa!D9*1,"") | E9: =IF(alfa!E9<>"",alfa!E9,"") | F9: =IF(D9="","",IF(OR(E9="",E9="невыясн"),"!",""))
A10: =IF(alfa!A10<>"",alfa!A10,"") | B10: =IF(alfa!B10<>"",alfa!B10,"") | C10: =IF(alfa!C10<>"",alfa!C10,"") | D10: =IF(AND(alfa!D10<>"",alfa!D10<>" "),alfa!D10*1,"") | E10: =IF(alfa!E10<>"",alfa!E10,"") | F10: =IF(D10="","",IF(OR(E10="",E10="невыясн"),"!",""))
A11: =IF(alfa!A11<>"",alfa!A11,"") | B11: =IF(alfa!B11<>"",alfa!B11,"") | C11: =IF(alfa!C11<>"",alfa!C11,"") | D11: =IF(AND(alfa!D11<>"",alfa!D11<>" "),alfa!D11*1,"") | E11: проч | F11: =IF(D11="","",IF(OR(E11="",E11="невыясн"),"!",""))
A12: =IF(alfa!A12<>"",alfa!A12,"") | B12: =IF(alfa!B12<>"",alfa!B12,"") | C12: =IF(alfa!C12<>"",alfa!C12,"") | D12: =IF(AND(alfa!D12<>"",alfa!D12<>" "),alfa!D12*1,"") | E12: =IF(alfa!E12<>"",alfa!E12,"") | F12: =IF(D12="","",IF(OR(E12="",E12="невыясн"),"!",""))
A13: =IF(alfa!A13<>"",alfa!A13,"") | B13: =IF(alfa!B13<>"",alfa!B13,"") | C13: =IF(alfa!C13<>"",alfa!C13,"") | D13: =IF(AND(alfa!D13<>"",alfa!D13<>" "),alfa!D13*1,"") | E13: =IF(alfa!E13<>"",alfa!E13,"") | F13: =IF(D13="","",IF(OR(E13="",E13="невыясн"),"!",""))
A14: =IF(alfa!A14<>"",alfa!A14,"") | B14: =IF(alfa!B14<>"",alfa!B14,"") | C14: =IF(alfa!C14<>"",alfa!C14,"") | D14: =IF(AND(alfa!D14<>"",alfa!D14<>" "),alfa!D14*1,"") | E14: =IF(alfa!E14<>"",alfa!E14,"") | F14: =IF(D14="","",IF(OR(E14="",E14="невыясн"),"!",""))
A15: =IF(alfa!A15<>"",alfa!A15,"") | B15: =IF(alfa!B15<>"",alfa!B15,"") | C15: =IF(alfa!C15<>"",alfa!C15,"") | D15: =IF(AND(alfa!D15<>"",alfa!D15<>" "),alfa!D15*1,"") | E15: =IF(alfa!E15<>"",alfa!E15,"") | F15: =IF(D15="","",IF(OR(E15="",E15="невыясн"),"!",""))
A16: =IF(alfa!A16<>"",alfa!A16,"") | B16: =IF(alfa!B16<>"",alfa!B16,"") | C16: =IF(alfa!C16<>"",alfa!C16,"") | D16: =IF(AND(alfa!D16<>"",alfa!D16<>" "),alfa!D16*1,"") | E16: =IF(alfa!E16<>"",alfa!E16,"") | F16: =IF(D16="","",IF(OR(E16="",E16="невыясн"),"!",""))
A17: =IF(alfa!A17<>"",alfa!A17,"") | B17: =IF(alfa!B17<>"",alfa!B17,"") | C17: =IF(alfa!C17<>"",alfa!C17,"") | D17: =IF(AND(alfa!D17<>"",alfa!D17<>" "),alfa!D17*1,"") | E17: проч | F17: =IF(D17="","",IF(OR(E17="",E17="невыясн"),"!",""))
A18: =IF(alfa!A18<>"",alfa!A18,"") | B18: =IF(alfa!B18<>"",alfa!B18,"") | C18: =IF(alfa!C18<>"",alfa!C18,"") | D18: =IF(AND(alfa!D18<>"",alfa!D18<>" "),alfa!D18*1,"") | E18: перевод | F18: =IF(D18="","",IF(OR(E18="",E18="невыясн"),"!",""))
A19: =IF(alfa!A19<>"",alfa!A19,"") | B19: =IF(alfa!B19<>"",alfa!B19,"") | C19: =IF(alfa!C19<>"",alfa!C19,"") | D19: =IF(AND(alfa!D19<>"",alfa!D19<>" "),alfa!D19*1,"") | E19: =IF(alfa!E19<>"",alfa!E19,"") | F19: =IF(D19="","",IF(OR(E19="",E19="невыясн"),"!",""))
A20: =IF(alfa!A20<>"",alfa!A20,"") | B20: =IF(alfa!B20<>"",alfa!B20,"") | C20: =IF(alfa!C20<>"",alfa!C20,"") | D20: =IF(AND(alfa!D20<>"",alfa!D20<>" "),alfa!D20*1,"") | E20: =IF(alfa!E20<>"",alfa!E20,"") | F20: =IF(D20="","",IF(OR(E20="",E20="невыясн"),"!",""))
A21: =IF(alfa!A21<>"",alfa!A21,"") | B21: =IF(alfa!B21<>"",alfa!B21,"") | C21: =IF(alfa!C21<>"",alfa!C21,"") | D21: =IF(AND(alfa!D21<>"",alfa!D21<>" "),alfa!D21*1,"") | E21: =IF(alfa!E21<>"",alfa!E21,"") | F21: =IF(D21="","",IF(OR(E21="",E21="невыясн"),"!",""))
A22: =IF(alfa!A22<>"",alfa!A22,"") | B22: =IF(alfa!B22<>"",alfa!B22,"") | C22: =IF(alfa!C22<>"",alfa!C22,"") | D22: =IF(AND(alfa!D22<>"",alfa!D22<>" "),alfa!D22*1,"") | E22: перевод | F22: =IF(D22="","",IF(OR(E22="",E22="невыясн"),"!",""))
A23: =IF(alfa!A23<>"",alfa!A23,"") | B23: =IF(alfa!B23<>"",alfa!B23,"") | C23: =IF(alfa!C23<>"",alfa!C23,"") | D23: =IF(AND(alfa!D23<>"",alfa!D23<>" "),alfa!D23*1,"") | E23: =IF(alfa!E23<>"",alfa!E23,"") | F23: =IF(D23="","",IF(OR(E23="",E23="невыясн"),"!",""))
A24: =IF(alfa!A24<>"",alfa!A24,"") | B24: =IF(alfa!B24<>"",alfa!B24,"") | C24: =IF(alfa!C24<>"",alfa!C24,"") | D24: =IF(AND(alfa!D24<>"",alfa!D24<>" "),alfa!D24*1,"") | E24: =IF(alfa!E24<>"",alfa!E24,"") | F24: =IF(D24="","",IF(OR(E24="",E24="невыясн"),"!",""))
A25: =IF(alfa!A25<>"",alfa!A25,"") | B25: =IF(alfa!B25<>"",alfa!B25,"") | C25: =IF(alfa!C25<>"",alfa!C25,"") | D25: =IF(AND(alfa!D25<>"",alfa!D25<>" "),alfa!D25*1,"") | E25: перевод | F25: =IF(D25="","",IF(OR(E25="",E25="невыясн"),"!",""))
A26: =IF(alfa!A26<>"",alfa!A26,"") | B26: =IF(alfa!B26<>"",alfa!B26,"") | C26: =IF(alfa!C26<>"",alfa!C26,"") | D26: =IF(AND(alfa!D26<>"",alfa!D26<>" "),alfa!D26*1,"") | E26: =IF(alfa!E26<>"",alfa!E26,"") | F26: =IF(D26="","",IF(OR(E26="",E26="невыясн"),"!",""))
A27: =IF(alfa!A27<>"",alfa!A27,"") | B27: =IF(alfa!B27<>"",alfa!B27,"") | C27: =IF(alfa!C27<>"",alfa!C27,"") | D27: =IF(AND(alfa!D27<>"",alfa!D27<>" "),alfa!D27*1,"") | E27: =IF(alfa!E27<>"",alfa!E27,"") | F27: =IF(D27="","",IF(OR(E27="",E27="невыясн"),"!",""))
A28: =IF(alfa!A28<>"",alfa!A28,"") | B28: =IF(alfa!B28<>"",alfa!B28,"") | C28: =IF(alfa!C28<>"",alfa!C28,"") | D28: =IF(AND(alfa!D28<>"",alfa!D28<>" "),alfa!D28*1,"") | E28: =IF(alfa!E28<>"",alfa!E28,"") | F28: =IF(D28="","",IF(OR(E28="",E28="невыясн"),"!",""))
A29: =IF(alfa!A29<>"",alfa!A29,"") | B29: =IF(alfa!B29<>"",alfa!B29,"") | C29: =IF(alfa!C29<>"",alfa!C29,"") | D29: =IF(AND(alfa!D29<>"",alfa!D29<>" "),alfa!D29*1,"") | E29: =IF(alfa!E29<>"",alfa!E29,"") | F29: =IF(D29="","",IF(OR(E29="",E29="невыясн"),"!",""))
A30: =IF(alfa!A30<>"",alfa!A30,"") | B30: =IF(alfa!B30<>"",alfa!B30,"") | C30: =IF(alfa!C30<>"",alfa!C30,"") | D30: =IF(AND(alfa!D30<>"",alfa!D30<>" "),alfa!D30*1,"") | E30: =IF(alfa!E30<>"",alfa!E30,"") | F30: =IF(D30="","",IF(OR(E30="",E30="невыясн"),"!",""))
A31: =IF(alfa!A31<>"",alfa!A31,"") | B31: =IF(alfa!B31<>"",alfa!B31,"") | C31: =IF(alfa!C31<>"",alfa!C31,"") | D31: =IF(AND(alfa!D31<>"",alfa!D31<>" "),alfa!D31*1,"") | E31: =IF(alfa!E31<>"",alfa!E31,"") | F31: =IF(D31="","",IF(OR(E31="",E31="невыясн"),"!",""))
A32: =IF(alfa!A32<>"",alfa!A32,"") | B32: =IF(alfa!B32<>"",alfa!B32,"") | C32: =IF(alfa!C32<>"",alfa!C32,"") | D32: =IF(AND(alfa!D32<>"",alfa!D32<>" "),alfa!D32*1,"") | E32: перевод | F32: =IF(D32="","",IF(OR(E32="",E32="невыясн"),"!",""))
A33: =IF(alfa!A33<>"",alfa!A33,"") | B33: =IF(alfa!B33<>"",alfa!B33,"") | C33: =IF(alfa!C33<>"",alfa!C33,"") | D33: =IF(AND(alfa!D33<>"",alfa!D33<>" "),alfa!D33*1,"") | E33: =IF(alfa!E33<>"",alfa!E33,"") | F33: =IF(D33="","",IF(OR(E33="",E33="невыясн"),"!",""))
A34: =IF(alfa!A34<>"",alfa!A34,"") | B34: =IF(alfa!B34<>"",alfa!B34,"") | C34: =IF(alfa!C34<>"",alfa!C34,"") | D34: =IF(AND(alfa!D34<>"",alfa!D34<>" "),alfa!D34*1,"") | E34: =IF(alfa!E34<>"",alfa!E34,"") | F34: =IF(D34="","",IF(OR(E34="",E34="невыясн"),"!",""))
A35: =IF(alfa!A35<>"",alfa!A35,"") | B35: =IF(alfa!B35<>"",alfa!B35,"") | C35: =IF(alfa!C35<>"",alfa!C35,"") | D35: =IF(AND(alfa!D35<>"",alfa!D35<>" "),alfa!D35*1,"") | E35: =IF(alfa!E35<>"",alfa!E35,"") | F35: =IF(D35="","",IF(OR(E35="",E35="невыясн"),"!",""))
A36: =IF(alfa!A36<>"",alfa!A36,"") | B36: =IF(alfa!B36<>"",alfa!B36,"") | C36: =IF(alfa!C36<>"",alfa!C36,"") | D36: =IF(AND(alfa!D36<>"",alfa!D36<>" "),alfa!D36*1,"") | E36: =IF(alfa!E36<>"",alfa!E36,"") | F36: =IF(D36="","",IF(OR(E36="",E36="невыясн"),"!",""))
A37: =IF(alfa!A37<>"",alfa!A37,"") | B37: =IF(alfa!B37<>"",alfa!B37,"") | C37: =IF(alfa!C37<>"",alfa!C37,"") | D37: =IF(AND(alfa!D37<>"",alfa!D37<>" "),alfa!D37*1,"") | E37: =IF(alfa!E37<>"",alfa!E37,"") | F37: =IF(D37="","",IF(OR(E37="",E37="невыясн"),"!",""))
A38: =IF(alfa!A38<>"",alfa!A38,"") | B38: =IF(alfa!B38<>"",alfa!B38,"") | C38: =IF(alfa!C38<>"",alfa!C38,"") | D38: =IF(AND(alfa!D38<>"",alfa!D38<>" "),alfa!D38*1,"") | E38: =IF(alfa!E38<>"",alfa!E38,"") | F38: =IF(D38="","",IF(OR(E38="",E38="невыясн"),"!",""))
A39: =IF(alfa!A39<>"",alfa!A39,"") | B39: =IF(alfa!B39<>"",alfa!B39,"") | C39: =IF(alfa!C39<>"",alfa!C39,"") | D39: =IF(AND(alfa!D39<>"",alfa!D39<>" "),alfa!D39*1,"") | E39: =IF(alfa!E39<>"",alfa!E39,"") | F39: =IF(D39="","",IF(OR(E39="",E39="невыясн"),"!",""))
A40: =IF(alfa!A40<>"",alfa!A40,"") | B40: =IF(alfa!B40<>"",alfa!B40,"") | C40: =IF(alfa!C40<>"",alfa!C40,"") | D40: =IF(AND(alfa!D40<>"",alfa!D40<>" "),alfa!D40*1,"") | E40: =IF(alfa!E40<>"",alfa!E40,"") | F40: =IF(D40="","",IF(OR(E40="",E40="невыясн"),"!",""))
...

Sheet Лист2
E1: Столбец1 | I1: Столбец1
A2: -299 | B2: проч | E2: комм.пл | H2: 33 | I2: нал
A3: -1850 | B3: Ек | E3: подписки | H3: 32 | I3: бонус
A4: -1100 | B4: комм.пл | D4: 1 | E4: Б % | H4: 31 | I4: з/п
A5: -1400 | B5: Ек | D5: 2 | E5: Б усл | H5: 30 | I5: аренда
A6: -449 | B6: подписки | D6: 3 | E6: кредит | H6: 29 | I6: перевод
A7: -1000 | B7: Ар | D7: 4 | E7: супер.м | H7: 28 | I7: проч
A8: -60000 | B8: перевод | D8: 5 | E8: ReCa | H8: 27 | I8: невыясн
A9: -16000 | B9: Ар | D9: 6 | E9: маркет.п | H9: 26 | I9: ZOO
A10: 76747.41 | B10: з/п | D10: 7 | E10: Од&О | H10: 25 | I10: Ар
A11: 7409 | B11: проч | D11: 8 | E11: Кр&З | H11: 24 | I11: Ан
A12: -1295 | B12: Ек | D12: 9 | E12: мед&ап | H12: 23 | I12: Ек
A13: -10000 | B13: перевод | D13: 10 | E13: бензин | H13: 22 | I13: а/б ж.д
A14: -1000 | B14: Ек | D14: 11 | E14: авто | H14: 21 | I14: Отдых
A15: -2000 | B15: перевод | D15: 12 | E15: TAXI | H15: 20 | I15: Спорт.т
... A34: -1000 | B34: Ек | D34: 31 | E34: нал | H34: 1 | I34: комм.пл
A35: -1556 | B35: Од&О | D35: 32
A36: -208000 | B36: нал | D36: 33
A37: 79697.02 | B37: з/п
A38: 108736.93 | B38: з/п
A39: -101.88 | B39: авто
A40: -6000 | B40: перевод
A41: -200 | B41: Ек
A42: -200 | B42: Ек
A43: -99 | B43: подписки
A44: -10000 | B44: Ар
A45: -4008 | B45: бензин
A46: -1049 | B46: подписки
A47: -1479.2 | B47: супер.м

Sheet Лист3
A1: =SUM(A3:A201) | B1: =SUM(B3:B201) | C1: =SUM(C3:C201) | D1: =SUM(D3:D201) | E1: =SUM(E3:E201) | F1: =SUM(F3:F201) | G1: =SUM(G3:G201) | H1: =SUM(H3:H201) | ... AI1: =SUM(AI3:AI201)
A2: комм.пл | B2: подписки | C2: Б % | D2: Б усл | E2: кредит | F2: супер.м | G2: ReCa | H2: маркет.п | I2: Од&О | J2: Кр&З | K2: мед&ап | L2: бензин | M2: авто | N2: TAXI | O2: трансп | P2: Дет&канц | Q2: Дом&рем | R2: развл&экс | S2: тех&под | T2: Спорт.т | U2: Отдых | V2: а/б ж.д | W2: Ек | X2: Ан | Y2: Ар | Z2: ZOO | AA2: невыясн | AB2: проч | AC2: перевод | AD2: аренда | AE2: з/п | AF2: бонус | AG2: нал
A3: -1100 | B3: -449 | E3: -30566.71 | F3: 488 | I3: -1556 | L3: -4008 | M3: -101.88 | W3: -1850 | Y3: -1000 | AB3: -299 | AC3: -60000 | AE3: 76747.41 | AG3: -208000
A4: -464.3 | B4: -99 | E4: -7333.29 | F4: -4127.08 | W4: -1400 | Y4: -16000 | AB4: 7409 | AC4: -10000 | AE4: 79697.02
A5: -4469.45 | B5: -1049 | F5: -1479.2 | W5: -1295 | Y5: -1000 | AB5: -1.13 | AC5: -2000 | AE5: 108736.93
A6: -1104.4 | W6: -1000 | Y6: -11000 | AB6: 15695 | AC6: 4000
W7: -580.84 | Y7: -4000 | AC7: 400
W8: -70 | Y8: -10000 | AC8: 3500
W9: -1000 | AC9: 20000
W10: -200 | AC10: -6000
W11: -200

Sheet Лист4
A1: ВСЕГО: | B1: =SUM(B2:B34)
A2: комм.пл | B2: -7138.15
A3: подписки | B3: -1597
A4: Б % | B4: 0
A5: Б усл | B5: 0
A6: кредит | B6: -37900
A7: супер.м | B7: -5118.28
A8: ReCa | B8: 0
A9: маркет.п | B9: 0
A10: Од&О | B10: -1556
A11: Кр&З | B11: 0
A12: мед&ап | B12: 0
A13: бензин | B13: -4008
... A34: нал | B34: -208000
